<?xml version="1.0" ?>
<sdf version="1.10">
    <world name="shadow_world">
        <physics name="1ms" type="ignored">
            <max_step_size>0.001</max_step_size>
            <real_time_factor>1.0</real_time_factor>
        </physics>
        <plugin
            filename="libgz-sim-physics-system.so"
            name="gz::sim::systems::Physics">
        </plugin>
        <plugin
            filename="libgz-sim-scene-broadcaster-system.so"
            name="gz::sim::systems::SceneBroadcaster">
        </plugin>
        <!-- IMU sensor -->
        <plugin filename="libgz-sim-imu-system.so"
            name="gz::sim::systems::Imu">
        </plugin>
        <!-- Contact sensor -->
        <plugin filename="libgz-sim-contact-system.so"
            name="gz::sim::systems::Contact">
        </plugin>
        <!-- Lidar sensor -->
        <plugin
            filename="libgz-sim-sensors-system.so"
            name="gz::sim::systems::Sensors">
            <render_engine>ogre2</render_engine>
        </plugin>

        <gui fullscreen="0">
            <!-- 3D scene -->
            <plugin filename="MinimalScene" name="3D View">
                <gz-gui>
                    <title>3D View</title>
                    <property type="bool" key="showTitleBar">false</property>
                    <property type="string" key="state">docked</property>
                </gz-gui>

                <engine>ogre2</engine>
                <scene>scene</scene>
                <ambient_light>0.4 0.4 0.4</ambient_light>
                <background_color>0.8 0.8 0.8</background_color>
                <camera_pose>-6 0 6 0 0.5 0</camera_pose>
            </plugin>

            <!-- Plugins that add functionality to the scene -->
            <plugin filename="EntityContextMenuPlugin" name="Entity context menu">
                <gz-gui>
                    <property key="state" type="string">floating</property>
                    <property key="width" type="double">5</property>
                    <property key="height" type="double">5</property>
                    <property key="showTitleBar" type="bool">false</property>
                </gz-gui>
            </plugin>
            <plugin filename="GzSceneManager" name="Scene Manager">
                <gz-gui>
                    <property key="resizable" type="bool">false</property>
                    <property key="width" type="double">5</property>
                    <property key="height" type="double">5</property>
                    <property key="state" type="string">floating</property>
                    <property key="showTitleBar" type="bool">false</property>
                </gz-gui>
            </plugin>
            <plugin filename="InteractiveViewControl" name="Interactive view control">
                <gz-gui>
                    <property key="resizable" type="bool">false</property>
                    <property key="width" type="double">5</property>
                    <property key="height" type="double">5</property>
                    <property key="state" type="string">floating</property>
                    <property key="showTitleBar" type="bool">false</property>
                </gz-gui>
            </plugin>
            <plugin filename="CameraTracking" name="Camera Tracking">
                <gz-gui>
                    <property key="resizable" type="bool">false</property>
                    <property key="width" type="double">5</property>
                    <property key="height" type="double">5</property>
                    <property key="state" type="string">floating</property>
                    <property key="showTitleBar" type="bool">false</property>
                </gz-gui>
            </plugin>
            <!-- World control -->
            <plugin filename="WorldControl" name="World control">
                <gz-gui>
                    <title>World control</title>
                    <property type="bool" key="showTitleBar">false</property>
                    <property type="bool" key="resizable">false</property>
                    <property type="double" key="height">72</property>
                    <property type="double" key="width">121</property>
                    <property type="double" key="z">1</property>

                    <property type="string" key="state">floating</property>
                    <anchors target="3D View">
                        <line own="left" target="left"/>
                        <line own="bottom" target="bottom"/>
                    </anchors>
                </gz-gui>

                <play_pause>true</play_pause>
                <step>true</step>
                <start_paused>true</start_paused>
                <use_event>true </use_event>
            </plugin>

            <plugin filename="ImageDisplay" name="Image Display">
                <gz-gui>
                    <property key="state" type="string">docked</property>
                </gz-gui>
                <topic>depth_camera</topic>
            </plugin>

            <plugin filename="ImageDisplay" name="Image Display">
                <gz-gui>
                    <property key="state" type="string">docked</property>
                </gz-gui>
                <topic>camera</topic>
            </plugin>
        </gui>

        <light type="directional" name="sun">
            <cast_shadows>true</cast_shadows>
            <pose>0 0 10 0 0 0</pose>
            <diffuse>0.8 0.8 0.8 1</diffuse>
            <specular>0.2 0.2 0.2 1</specular>
            <attenuation>
                <range>1000</range>
                <constant>0.9</constant>
                <linear>0.01</linear>
                <quadratic>0.001</quadratic>
            </attenuation>
            <direction>-0.5 0.1 -0.9</direction>
        </light>

        <model name="ground_plane">
            <static>true</static>
            <link name="link">
                <collision name="collision">
                <geometry>
                    <plane>
                    <normal>0 0 1</normal>
                    </plane>
                </geometry>
                </collision>
                <visual name="visual">
                <geometry>
                    <plane>
                    <normal>0 0 1</normal>
                    <size>100 100</size>
                    </plane>
                </geometry>
                <material>
                    <ambient>0.8 0.8 0.8 1</ambient>
                    <diffuse>0.8 0.8 0.8 1</diffuse>
                    <specular>0.8 0.8 0.8 1</specular>
                </material>
                </visual>
            </link>
        </model>

        <model name='vehicle_blue' canonical_link='chassis'>
            <pose relative_to='world'>0 0 0 0 0 0</pose>
            <link name='chassis'>
                <pose relative_to='__model__'>0.5 0 0.05 0 0 0</pose>
                <inertial> <!--inertial properties of the link mass, inertia matix-->
                    <mass>16.5</mass>
                    <inertia>
                        <ixx>0.095329</ixx>
                        <ixy>0</ixy>
                        <ixz>0</ixz>
                        <iyy>0.381317</iyy>
                        <iyz>0</iyz>
                        <izz>0.476646</izz>
                    </inertia>
                </inertial>
                <visual name='visual'>
                    <geometry>
                        <mesh>
                            <uri>file://assets/shadow.dae</uri>
                        </mesh>
                    </geometry>
                    <!--let's add color to our link-->
                    <material>
                        <ambient>0.0 0.0 1.0 1</ambient>
                        <diffuse>0.0 0.0 1.0 1</diffuse>
                        <specular>0.0 0.0 1.0 1</specular>
                    </material>
                </visual>
                <collision name='collision'>
                    <geometry>
                        <mesh>
                            <uri>file://assets/shadow_collision.dae</uri>
                        </mesh>
                    </geometry>
                </collision>

                <!-- IMU Sensor -->
                <sensor name="imu_sensor" type="imu">
                    <always_on>1</always_on>
                    <update_rate>1</update_rate>
                    <visualize>true</visualize>
                    <topic>imu</topic>
                </sensor>

                <!-- Lidar Sensor-->
                <sensor name='gpu_lidar' type='gpu_lidar'>"
                    <pose relative_to='lidar_frame'>0 0 0 0 0 0</pose>
                    <topic>lidar</topic>
                    <update_rate>10</update_rate>
                    <ray>
                        <scan>
                            <horizontal>
                                <samples>640</samples>
                                <resolution>1</resolution>
                                <min_angle>0</min_angle>
                                <max_angle>6.28</max_angle>
                            </horizontal>
                            <vertical>
                                <samples>1</samples>
                                <resolution>0.01</resolution>
                                <min_angle>0</min_angle>
                                <max_angle>0</max_angle>
                            </vertical>
                        </scan>
                        <range>
                            <min>0.08</min>
                            <max>10.0</max>
                            <resolution>0.01</resolution>
                        </range>
                    </ray>
                    <always_on>1</always_on>
                    <visualize>true</visualize>
                </sensor>

                <!-- Depth Camera sensor -->
                <sensor name="depth_camera" type="depth_camera">
                    <pose relative_to='lidar_frame'>0 0 0 0 0 0</pose>
                    <update_rate>10</update_rate>
                    <topic>depth_camera</topic>
                    <camera>
                        <horizontal_fov>1.05</horizontal_fov>
                        <image>
                            <width>256</width>
                            <height>256</height>
                            <format>R_FLOAT32</format>
                        </image>
                        <clip>
                            <near>0.1</near>
                            <far>10.0</far>
                        </clip>
                    </camera>
                    <always_on>1</always_on>
                </sensor>

                <!-- RGB Camera sensor -->
                <sensor name="camera" type="camera">
                  <camera>
                    <horizontal_fov>1.047</horizontal_fov>
                    <image>
                      <width>320</width>
                      <height>240</height>
                    </image>
                    <clip>
                      <near>0.1</near>
                      <far>100</far>
                    </clip>
                  </camera>
                  <pose relative_to='lidar_frame'>0 0 0 0 0 0</pose>
                  <always_on>1</always_on>
                  <update_rate>30</update_rate>
                  <visualize>true</visualize>
                  <topic>camera</topic>
                </sensor>

            </link>

            
            <!-- ******************************* WHEELS ********************************** -->
            <link name='left_back_wheel'>
                <pose relative_to="chassis">-0.11 0.2 0.02 -1.5707 0 0</pose>
                <inertial>
                    <mass>1</mass>
                    <inertia>
                        <ixx>0.043333</ixx>
                        <ixy>0</ixy>
                        <ixz>0</ixz>
                        <iyy>0.043333</iyy>
                        <iyz>0</iyz>
                        <izz>0.085</izz>
                    </inertia>
                </inertial>
                <visual name='visual'>
                    <geometry>
                        <cylinder>
                            <radius>0.07</radius>
                            <length>0.07</length>
                        </cylinder>
                    </geometry>
                    <material>
                        <ambient>1.0 0.0 0.0 1</ambient>
                        <diffuse>1.0 0.0 0.0 1</diffuse>
                        <specular>1.0 0.0 0.0 1</specular>
                    </material>
                </visual>
                <collision name='collision'>
                    <geometry>
                        <cylinder>
                            <radius>0.07</radius>
                            <length>0.07</length>
                        </cylinder>
                    </geometry>
                </collision>
            </link>

            <link name='right_back_wheel'>
                <pose relative_to="chassis">-0.11 -0.2 0.02 -1.5707 0 0</pose>
                <inertial>
                    <mass>1</mass>
                    <inertia>
                        <ixx>0.043333</ixx>
                        <ixy>0</ixy>
                        <ixz>0</ixz>
                        <iyy>0.043333</iyy>
                        <iyz>0</iyz>
                        <izz>0.08</izz>
                    </inertia>
                </inertial>
                <visual name='visual'>
                    <geometry>
                        <cylinder>
                            <radius>0.07</radius>
                            <length>0.07</length>
                        </cylinder>
                    </geometry>
                    <material>
                        <ambient>1.0 0.0 0.0 1</ambient>
                        <diffuse>1.0 0.0 0.0 1</diffuse>
                        <specular>1.0 0.0 0.0 1</specular>
                    </material>
                </visual>
                <collision name='collision'>
                    <geometry>
                        <cylinder>
                            <radius>0.07</radius>
                            <length>0.07</length>
                        </cylinder>
                    </geometry>
                </collision>
            </link>

            <link name='left_front_wheel'>
                <pose relative_to="chassis">0.11 0.2 0.02 -1.5707 0 0</pose>
                <inertial>
                    <mass>1</mass>
                    <inertia>
                        <ixx>0.043333</ixx>
                        <ixy>0</ixy>
                        <ixz>0</ixz>
                        <iyy>0.043333</iyy>
                        <iyz>0</iyz>
                        <izz>0.08</izz>
                    </inertia>
                </inertial>
                <visual name='visual'>
                    <geometry>
                        <cylinder>
                            <radius>0.07</radius>
                            <length>0.07</length>
                        </cylinder>
                    </geometry>
                    <material>
                        <ambient>1.0 0.0 0.0 1</ambient>
                        <diffuse>1.0 0.0 0.0 1</diffuse>
                        <specular>1.0 0.0 0.0 1</specular>
                    </material>
                </visual>
                <collision name='collision'>
                    <geometry>
                        <cylinder>
                            <radius>0.07</radius>
                            <length>0.07</length>
                        </cylinder>
                    </geometry>
                </collision>
            </link>

            <link name='right_front_wheel'>
                <pose relative_to="chassis">0.11 -0.2 0.02 -1.5707 0 0</pose>
                <inertial>
                    <mass>1</mass>
                    <inertia>
                        <ixx>0.043333</ixx>
                        <ixy>0</ixy>
                        <ixz>0</ixz>
                        <iyy>0.043333</iyy>
                        <iyz>0</iyz>
                        <izz>0.08</izz>
                    </inertia>
                </inertial>
                <visual name='visual'>
                    <geometry>
                        <cylinder>
                            <radius>0.07</radius>
                            <length>0.07</length>
                        </cylinder>
                    </geometry>
                    <material>
                        <ambient>1.0 0.0 0.0 1</ambient>
                        <diffuse>1.0 0.0 0.0 1</diffuse>
                        <specular>1.0 0.0 0.0 1</specular>
                    </material>
                </visual>
                <collision name='collision'>
                    <geometry>
                        <cylinder>
                            <radius>0.07</radius>
                            <length>0.07</length>
                        </cylinder>
                    </geometry>
                </collision>
            </link>

            <joint name='left_back_wheel_joint' type='revolute'>
                <pose relative_to='left_back_wheel'/>
                <parent>chassis</parent>
                <child>left_back_wheel</child>
                <axis>
                    <xyz expressed_in='__model__'>0 1 0</xyz> <!--can be defined as any frame or even arbitrary frames-->
                    <limit>
                        <lower>-1.79769e+308</lower>    <!--negative infinity-->
                        <upper>1.79769e+308</upper>     <!--positive infinity-->
                    </limit>
                </axis>
            </joint>

            <joint name='right_back_wheel_joint' type='revolute'>
                <pose relative_to='right_back_wheel'/>
                <parent>chassis</parent>
                <child>right_back_wheel</child>
                <axis>
                    <xyz expressed_in='__model__'>0 1 0</xyz>
                    <limit>
                        <lower>-1.79769e+308</lower>    <!--negative infinity-->
                        <upper>1.79769e+308</upper>     <!--positive infinity-->
                    </limit>
                </axis>
            </joint>

            <joint name='left_front_wheel_joint' type='revolute'>
                <pose relative_to='left_front_wheel'/>
                <parent>chassis</parent>
                <child>left_front_wheel</child>
                <axis>
                    <xyz expressed_in='__model__'>0 1 0</xyz> <!--can be defined as any frame or even arbitrary frames-->
                    <limit>
                        <lower>-1.79769e+308</lower>    <!--negative infinity-->
                        <upper>1.79769e+308</upper>     <!--positive infinity-->
                    </limit>
                </axis>
            </joint>

            <joint name='right_front_wheel_joint' type='revolute'>
                <pose relative_to='right_front_wheel'/>
                <parent>chassis</parent>
                <child>right_front_wheel</child>
                <axis>
                    <xyz expressed_in='__model__'>0 1 0</xyz>
                    <limit>
                        <lower>-1.79769e+308</lower>    <!--negative infinity-->
                        <upper>1.79769e+308</upper>     <!--positive infinity-->
                    </limit>
                </axis>
            </joint>

            <!-- *************************** LIDAR FRAME ****************************** -->
            <frame name="lidar_frame" attached_to='chassis'>
                <pose>0.8 0 0.5 0 0 0</pose>
            </frame>

            <plugin
                filename="libgz-sim-diff-drive-system.so"
                name="gz::sim::systems::DiffDrive">
                <left_joint>left_back_wheel_joint</left_joint>
                <left_joint>left_front_wheel_joint</left_joint>
                <right_joint>right_back_wheel_joint</right_joint>
                <right_joint>right_front_wheel_joint</right_joint>
                <wheel_separation>0.4</wheel_separation>
                <wheel_radius>0.07</wheel_radius>
                <odom_publish_frequency>1</odom_publish_frequency>
                <topic>cmd_vel</topic>
            </plugin>

        </model>

        <model name='wall'>
            <static>true</static>
            <pose>5 0 0 0 0 0</pose><!--pose relative to the world-->
            <link name='box'>
                <pose/>
                <visual name='visual'>
                    <geometry>
                        <box>
                            <size>0.5 10.0 2.0</size>
                        </box>
                    </geometry>
                    <!--let's add color to our link-->
                    <material>
                        <ambient>0.0 0.0 1.0 1</ambient>
                        <diffuse>0.0 0.0 1.0 1</diffuse>
                        <specular>0.0 0.0 1.0 1</specular>
                    </material>
                </visual>
                <collision name='collision'>
                    <geometry>
                        <box>
                            <size>0.5 10.0 2.0</size>
                        </box>
                    </geometry>
                </collision>

                <sensor name='sensor_contact' type='contact'>
                    <contact>
                        <collision>collision</collision>
                    </contact>
                </sensor>
            </link>

            <!-- Touch Plugin -->
            <plugin filename="libgz-sim-touchplugin-system.so"
                name="gz::sim::systems::TouchPlugin">
                <target>vehicle_blue</target>
                <namespace>wall</namespace>
                <time>0.001</time>
                <enabled>true</enabled>
            </plugin>

        </model>

        <!-- Moving Forward-->
        <plugin filename="libgz-sim-triggered-publisher-system.so"
                name="gz::sim::systems::TriggeredPublisher">
            <input type="gz.msgs.Int32" topic="/keyboard/keypress">
                <match field="data">16777235</match>
            </input>
            <output type="gz.msgs.Twist" topic="/cmd_vel">
                linear: {x: 0.5}, angular: {z: 0.0}
            </output>
        </plugin>
        
        <!-- Moving Backwards-->
        <plugin filename="libgz-sim-triggered-publisher-system.so"
                name="gz::sim::systems::TriggeredPublisher">
            <input type="gz.msgs.Int32" topic="/keyboard/keypress">
                <match field="data">16777237</match>
            </input>
            <output type="gz.msgs.Twist" topic="/cmd_vel">
                linear: {x: -0.5}, angular: {z: 0.0}
            </output>
        </plugin>

        <!-- Moving Right-->
        <plugin filename="libgz-sim-triggered-publisher-system.so"
                name="gz::sim::systems::TriggeredPublisher">
            <input type="gz.msgs.Int32" topic="/keyboard/keypress">
                <match field="data">16777236</match>
            </input>
            <output type="gz.msgs.Twist" topic="/cmd_vel">
                linear: {x: 0.0}, angular: {z: -0.5}
            </output>
        </plugin>

        <!-- Moving Left-->
        <plugin filename="libgz-sim-triggered-publisher-system.so"
                name="gz::sim::systems::TriggeredPublisher">
            <input type="gz.msgs.Int32" topic="/keyboard/keypress">
                <match field="data">16777234</match>
            </input>
            <output type="gz.msgs.Twist" topic="/cmd_vel">
                linear: {x: 0.0}, angular: {z: 0.5}
            </output>
        </plugin>

        <plugin filename="libgz-sim-triggered-publisher-system.so"
                name="gz::sim::systems::TriggeredPublisher">
            <input type="gz.msgs.Boolean" topic="/wall/touched">
                <match>data: true</match>
            </input>
            <output type="gz.msgs.Twist" topic="/cmd_vel">
                linear: {x: 0.0}, angular: {z: 0.0}
            </output>
        </plugin>

    </world>


</sdf>
