<?xml version="1.0"?>
<sdf version="1.6">
    <model name='shadow' canonical_link='chassis'>
        <link name='chassis'>
            <pose relative_to='__model__'>0.5 0 0.05 0 0 0</pose>
            <inertial> <!--inertial properties of the link mass, inertia matix-->
                <mass>8.482e-01</mass>
                <inertia>
                    <ixx>3.022e-02</ixx>
                    <ixy>0</ixy>
                    <ixz>0</ixz>
                    <iyy>3.022e-02</iyy>
                    <iyz>0</iyz>
                    <izz>1.125e-04</izz>
                </inertia>
            </inertial>
            <visual name='visual'>
                <geometry>
                    <mesh>
                        <uri>model://Robot_Shadow/meshes/shadow.dae</uri>
                    </mesh>
                </geometry>
                <!--let's add color to our link-->
                <material>
                    <ambient>0.0 0.0 1.0 1</ambient>
                    <diffuse>0.0 0.0 1.0 1</diffuse>
                    <specular>0.0 0.0 1.0 1</specular>
                </material>
            </visual>
            <collision name='collision'>
                <geometry>
                    <mesh>
                        <uri>model://Robot_Shadow/meshes/shadow_collision.stl</uri>
                    </mesh>
                </geometry>
            </collision>

            <!-- IMU Sensor -->
            <sensor name="imu_sensor" type="imu">
                <always_on>1</always_on>
                <update_rate>1</update_rate>
                <visualize>true</visualize>
                <topic>imu</topic>
            </sensor>

            <!-- Lidar Sensor-->
            <sensor name='gpu_lidar' type='gpu_lidar'>"
                <pose relative_to='lidar_frame'>0 0 0 0 0 0</pose>
                <topic>lidar</topic>
                <update_rate>10</update_rate>
                <ray>
                    <scan>
                        <horizontal>
                            <samples>640</samples>
                            <resolution>1</resolution>
                            <min_angle>0</min_angle>
                            <max_angle>6.28</max_angle>
                        </horizontal>
                        <vertical>
                            <samples>1</samples>
                            <resolution>0.01</resolution>
                            <min_angle>0</min_angle>
                            <max_angle>0</max_angle>
                        </vertical>
                    </scan>
                    <range>
                        <min>0.1</min>
                        <max>4</max>
                        <resolution>0.1</resolution>
                    </range>
                </ray>
                <always_on>1</always_on>
                <visualize>true</visualize>
            </sensor>

            <!-- Depth Camera sensor -->
            <sensor name="depth_camera" type="depth_camera">
                <pose relative_to='lidar_frame'>0 0 0 0 0 0</pose>
                <update_rate>10</update_rate>
                <topic>depth_camera</topic>
                <camera>
                    <horizontal_fov>1.05</horizontal_fov>
                    <image>
                        <width>256</width>
                        <height>256</height>
                        <format>R_FLOAT32</format>
                    </image>
                    <clip>
                        <near>0.1</near>
                        <far>10.0</far>
                    </clip>
                </camera>
                <always_on>1</always_on>
            </sensor>

            <!-- RGB Camera sensor -->
            <sensor name="camera" type="camera">
              <camera>
                <horizontal_fov>1.047</horizontal_fov>
                <image>
                  <width>320</width>
                  <height>240</height>
                </image>
                <clip>
                  <near>0.1</near>
                  <far>100</far>
                </clip>
              </camera>
              <pose relative_to='lidar_frame'>0 0 0 0 0 0</pose>
              <always_on>1</always_on>
              <update_rate>30</update_rate>
              <visualize>true</visualize>
              <topic>camera</topic>
            </sensor>

        </link>


        <!-- ******************************* WHEELS ********************************** -->
        <link name='left_back_wheel'>
            <pose relative_to="chassis">-0.11 0.2 0.02 -1.5707 0 0</pose>
            <inertial>
                <mass>6.202</mass>
                <inertia>
                    <ixx>4.586e-04</ixx>
                    <ixy>0</ixy>
                    <ixz>0</ixz>
                    <iyy>4.586e-04</iyy>
                    <iyz>0</iyz>
                    <izz>1.52e-04</izz>
                </inertia>
            </inertial>
            <visual name='visual'>
                <geometry>
                    <cylinder>
                        <radius>0.07</radius>
                        <length>0.07</length>
                    </cylinder>
                </geometry>
                <material>
                    <ambient>1.0 0.0 0.0 1</ambient>
                    <diffuse>1.0 0.0 0.0 1</diffuse>
                    <specular>1.0 0.0 0.0 1</specular>
                </material>
            </visual>
            <collision name='collision'>
                <geometry>
                    <cylinder>
                        <radius>0.07</radius>
                        <length>0.07</length>
                    </cylinder>
                </geometry>
            </collision>
        </link>

        <link name='right_back_wheel'>
            <pose relative_to="chassis">-0.11 -0.2 0.02 -1.5707 0 0</pose>
            <inertial>
                <mass>6.202</mass>
                <inertia>
                    <ixx>4.586e-04</ixx>
                    <ixy>0</ixy>
                    <ixz>0</ixz>
                    <iyy>4.586e-04</iyy>
                    <iyz>0</iyz>
                    <izz>1.52e-04</izz>
                </inertia>
            </inertial>
            <visual name='visual'>
                <geometry>
                    <cylinder>
                        <radius>0.07</radius>
                        <length>0.07</length>
                    </cylinder>
                </geometry>
                <material>
                    <ambient>1.0 0.0 0.0 1</ambient>
                    <diffuse>1.0 0.0 0.0 1</diffuse>
                    <specular>1.0 0.0 0.0 1</specular>
                </material>
            </visual>
            <collision name='collision'>
                <geometry>
                    <cylinder>
                        <radius>0.07</radius>
                        <length>0.07</length>
                    </cylinder>
                </geometry>
            </collision>
        </link>

        <link name='left_front_wheel'>
            <pose relative_to="chassis">0.11 0.2 0.02 -1.5707 0 0</pose>
            <inertial>
                <mass>6.202</mass>
                <inertia>
                    <ixx>4.586e-04</ixx>
                    <ixy>0</ixy>
                    <ixz>0</ixz>
                    <iyy>4.586e-04</iyy>
                    <iyz>0</iyz>
                    <izz>1.52e-04</izz>
                </inertia>
            </inertial>
            <visual name='visual'>
                <geometry>
                    <cylinder>
                        <radius>0.07</radius>
                        <length>0.07</length>
                    </cylinder>
                </geometry>
                <material>
                    <ambient>1.0 0.0 0.0 1</ambient>
                    <diffuse>1.0 0.0 0.0 1</diffuse>
                    <specular>1.0 0.0 0.0 1</specular>
                </material>
            </visual>
            <collision name='collision'>
                <geometry>
                    <cylinder>
                        <radius>0.07</radius>
                        <length>0.07</length>
                    </cylinder>
                </geometry>
            </collision>
        </link>

        <link name='right_front_wheel'>
            <pose relative_to="chassis">0.11 -0.2 0.02 -1.5707 0 0</pose>
            <inertial>
                <mass>6.202</mass>
                <inertia>
                    <ixx>4.586e-04</ixx>
                    <ixy>0</ixy>
                    <ixz>0</ixz>
                    <iyy>4.586e-04</iyy>
                    <iyz>0</iyz>
                    <izz>1.52e-04</izz>
                </inertia>
            </inertial>
            <visual name='visual'>
                <geometry>
                    <cylinder>
                        <radius>0.07</radius>
                        <length>0.07</length>
                    </cylinder>
                </geometry>
                <material>
                    <ambient>1.0 0.0 0.0 1</ambient>
                    <diffuse>1.0 0.0 0.0 1</diffuse>
                    <specular>1.0 0.0 0.0 1</specular>
                </material>
            </visual>
            <collision name='collision'>
                <geometry>
                    <cylinder>
                        <radius>0.07</radius>
                        <length>0.07</length>
                    </cylinder>
                </geometry>
            </collision>
        </link>

        <joint name='left_back_wheel_joint' type='revolute'>
            <pose relative_to='left_back_wheel'/>
            <parent>chassis</parent>
            <child>left_back_wheel</child>
            <axis>
                <xyz expressed_in='__model__'>0 1 0</xyz> <!--can be defined as any frame or even arbitrary frames-->
                <limit>
                    <lower>-1.79769e+308</lower>    <!--negative infinity-->
                    <upper>1.79769e+308</upper>     <!--positive infinity-->
                </limit>
            </axis>
        </joint>

        <joint name='right_back_wheel_joint' type='revolute'>
            <pose relative_to='right_back_wheel'/>
            <parent>chassis</parent>
            <child>right_back_wheel</child>
            <axis>
                <xyz expressed_in='__model__'>0 1 0</xyz>
                <limit>
                    <lower>-1.79769e+308</lower>    <!--negative infinity-->
                    <upper>1.79769e+308</upper>     <!--positive infinity-->
                </limit>
            </axis>
        </joint>

        <joint name='left_front_wheel_joint' type='revolute'>
            <pose relative_to='left_front_wheel'/>
            <parent>chassis</parent>
            <child>left_front_wheel</child>
            <axis>
                <xyz expressed_in='__model__'>0 1 0</xyz> <!--can be defined as any frame or even arbitrary frames-->
                <limit>
                    <lower>-1.79769e+308</lower>    <!--negative infinity-->
                    <upper>1.79769e+308</upper>     <!--positive infinity-->
                </limit>
            </axis>
        </joint>

        <joint name='right_front_wheel_joint' type='revolute'>
            <pose relative_to='right_front_wheel'/>
            <parent>chassis</parent>
            <child>right_front_wheel</child>
            <axis>
                <xyz expressed_in='__model__'>0 1 0</xyz>
                <limit>
                    <lower>-1.79769e+308</lower>    <!--negative infinity-->
                    <upper>1.79769e+308</upper>     <!--positive infinity-->
                </limit>
            </axis>
        </joint>

        <!-- *************************** LIDAR FRAME ****************************** -->
        <frame name="lidar_frame" attached_to='chassis'>
            <pose>0.8 0 0.5 0 0 0</pose>
        </frame>

        <!-- *************************** DIFFERENCIAL DRIVE ****************************** -->
        <plugin
            filename="libgz-sim-diff-drive-system.so"
            name="gz::sim::systems::DiffDrive">
            <left_joint>left_back_wheel_joint</left_joint>
            <left_joint>left_front_wheel_joint</left_joint>
            <right_joint>right_back_wheel_joint</right_joint>
            <right_joint>right_front_wheel_joint</right_joint>
            <wheel_separation>0.4</wheel_separation>
            <wheel_radius>0.07</wheel_radius>
            <odom_publish_frequency>10</odom_publish_frequency>
            <topic>cmd_vel</topic>
        </plugin>

    </model>
</sdf>